Workbook

Sheet Meals
A1: Meal log - one row per meal, calorie/protein/fat given as a low-high range
A2: Edit the blue cells only. Add a new meal as a new row directly under the last one, then re-run nutrition/build_tracker.py so the Daily and Trends sheets pick it up. Set status to "pending" for anything not yet confirmed eaten - pending rows are excluded from every total. Yellow rows are awaiting confirmation.
A4: Date | B4: Meal | C4: Items | D4: Cal low | E4: Cal high | F4: Cal mid | G4: Protein low (g) | H4: Protein high (g) | I4: Protein mid (g) | J4: Fat low (g) | K4: Fat high (g) | L4: Fat mid (g) | M4: Status | N4: Notes
A5: 46269 | B5: Breakfast | C5: Dosa + sambar + red chutney (coconut chutney skipped) | D5: 360 | E5: 450 | F5: =AVERAGE(D5:E5) | G5: 6 | H5: 9 | I5: =AVERAGE(G5:H5) | J5: 8 | K5: 12 | L5: =AVERAGE(J5:K5) | M5: logged
A6: 46269 | B6: Dinner | C6: 2 maida porotta + kadala curry | D6: 520 | E6: 800 | F6: =AVERAGE(D6:E6) | G6: 15 | H6: 21 | I6: =AVERAGE(G6:H6) | J6: 23 | K6: 38 | L6: =AVERAGE(J6:K6) | M6: logged | N6: Dropped from 3 to 2 porotta to tighten calories and fat
A7: 46269 | B7: Lunch | C7: Chicken biryani (half plate) + raita | D7: 500 | E7: 680 | F7: =AVERAGE(D7:E7) | G7: 25 | H7: 35 | I7: =AVERAGE(G7:H7) | J7: 18 | K7: 28 | L7: =AVERAGE(J7:K7) | M7: logged
A8: 46269 | B8: Snack | C8: Black coffee + 1 whey scoop | D8: 100 | E8: 130 | F8: =AVERAGE(D8:E8) | G8: 20 | H8: 25 | I8: =AVERAGE(G8:H8) | J8: 1 | K8: 3 | L8: =AVERAGE(J8:K8) | M8: logged
A9: 46269 | B9: Snack | C9: 1 cookie (cashew/almond biscuit) | D9: 38 | E9: 38 | F9: =AVERAGE(D9:E9) | G9: 0.5 | H9: 0.5 | I9: =AVERAGE(G9:H9) | J9: 2 | K9: 2 | L9: =AVERAGE(J9:K9) | M9: logged
A10: 46270 | B10: Breakfast | C10: 2 dosa + sambar + red chutney (coconut chutney skipped) | D10: 410 | E10: 520 | F10: =AVERAGE(D10:E10) | G10: 11 | H10: 15 | I10: =AVERAGE(G10:H10) | J10: 10 | K10: 17 | L10: =AVERAGE(J10:K10) | M10: logged
A11: 46270 | B11: Dinner | C11: Fresh pineapple juice (~350-450 ml takeaway cup) - no added sugar | D11: 175 | E11: 240 | F11: =AVERAGE(D11:E11) | G11: 1 | H11: 2 | I11: =AVERAGE(G11:H11) | J11: 0 | K11: 0.5 | L11: =AVERAGE(J11:K11) | M11: logged | N11: Juice only - no solid food at dinner. ~35-45 g natural sugar; no fibre; ~1.5 g protein
A12: 46270 | B12: Lunch | C12: Fish fry + ~half container barik rice + sambar + veg raita + red chutney + veg side | D12: 590 | E12: 840 | F12: =AVERAGE(D12:E12) | G12: 28 | H12: 39 | I12: =AVERAGE(G12:H12) | J12: 20 | K12: 33 | L12: =AVERAGE(J12:K12) | M12: logged
A13: 46270 | B13: Snack | C13: Black coffee + 1 whey scoop (no sugar) | D13: 100 | E13: 130 | F13: =AVERAGE(D13:E13) | G13: 20 | H13: 25 | I13: =AVERAGE(G13:H13) | J13: 1 | K13: 3 | L13: =AVERAGE(J13:K13) | M13: logged
A14: 46270 | B14: Snack | C14: 1 whey scoop + water | D14: 100 | E14: 120 | F14: =AVERAGE(D14:E14) | G14: 20 | H14: 25 | I14: =AVERAGE(G14:H14) | J14: 1 | K14: 2 | L14: =AVERAGE(J14:K14) | M14: logged
A15: 46270 | B15: Snack | C15: 3 uzhunnu vada + coconut chutney | D15: 480 | E15: 650 | F15: =AVERAGE(D15:E15) | G15: 11.5 | H15: 17 | I15: =AVERAGE(G15:H15) | J15: 29 | K15: 40 | L15: =AVERAGE(J15:K15) | M15: logged | N15: Coconut chutney included this time (skipped at breakfast both days)
A16: 46270 | B16: Supplement | C16: Pre-workout scoop | D16: 5 | E16: 15 | F16: =AVERAGE(D16:E16) | G16: 0 | H16: 0 | I16: =AVERAGE(G16:H16) | J16: 0 | K16: 0 | L16: =AVERAGE(J16:K16) | M16: pending | N16: Planned but not taken as of last check - confirm before logging
A17: 46271 | B17: Breakfast | C17: 2 maida porotta + kadala curry | D17: 520 | E17: 800 | F17: =AVERAGE(D17:E17) | G17: 15 | H17: 21 | I17: =AVERAGE(G17:H17) | J17: 23 | K17: 38 | L17: =AVERAGE(J17:K17) | M17: logged | N17: Ate 2 of the 3 served - deliberately cut one for calories; costed identically to Day 1 dinner
A18: 46271 | B18: Dinner | C18: Honest Bowl - Tofu Delight Bowl | D18: 420 | E18: 560 | F18: =AVERAGE(D18:E18) | G18: 18 | H18: 22 | I18: =AVERAGE(G18:H18) | J18: 15 | K18: 25 | L18: =AVERAGE(J18:K18) | M18: logged | N18: Menu states 20 g protein; jasmine rice + cajun tofu + grilled eggplant
A19: 46271 | B19: Dinner | C19: Chicken curry (1 takeaway container) | D19: 280 | E19: 420 | F19: =AVERAGE(D19:E19) | G19: 20 | H19: 28 | I19: =AVERAGE(G19:H19) | J19: 16 | K19: 26 | L19: =AVERAGE(J19:K19) | M19: logged | N19: Eaten alongside the tofu bowl
A20: 46271 | B20: Lunch | C20: Honest Bowl - Grilled Chicken and Rice Bowl | D20: 550 | E20: 710 | F20: =AVERAGE(D20:E20) | G20: 42 | H20: 48 | I20: =AVERAGE(G20:H20) | J20: 9 | K20: 18 | L20: =AVERAGE(J20:K20) | M20: logged | N20: Menu states 42 g protein; chicken + jasmine rice + sweet potato
A21: 46271 | B21: Snack | C21: Fresh orange juice (~350-450 ml) - no added sugar | D21: 155 | E21: 205 | F21: =AVERAGE(D21:E21) | G21: 2 | H21: 3 | I21: =AVERAGE(G21:H21) | J21: 0 | K21: 0.5 | L21: =AVERAGE(J21:K21) | M21: logged | N21: Second juice in three days; ~32-40 g natural sugar
A22: 46272 | B22: Breakfast | C22: 2 appam + potato curry (bhaji) | D22: 390 | E22: 520 | F22: =AVERAGE(D22:E22) | G22: 8 | H22: 11 | I22: =AVERAGE(G22:H22) | J22: 10 | K22: 18 | L22: =AVERAGE(J22:K22) | M22: logged | N22: Lightest breakfast in the log by calories; fourth straight breakfast under 20 g protein
A23: 46272 | B23: Dinner | C23: Chicken curry + 1 chapati | D23: 380 | E23: 550 | F23: =AVERAGE(D23:E23) | G23: 23 | H23: 32 | I23: =AVERAGE(G23:H23) | J23: 18 | K23: 30 | L23: =AVERAGE(J23:K23) | M23: logged | N23: Mess Monday dinner; took one chapati rather than two
A24: 46272 | B24: Lunch | C24: Mess meals plate (rice halved): rice, 2 boiled eggs, 1 fried fish, sambar, green peas, buttermilk, veg curry, fish curry | D24: 790 | E24: 1100 | F24: =AVERAGE(D24:E24) | G24: 37 | H24: 51 | I24: =AVERAGE(G24:H24) | J24: 28 | K24: 48 | L24: =AVERAGE(J24:K24) | M24: logged | N24: Rice was already the half portion - both levers pulled. Highest-protein single meal in the log
A25: 46272 | B25: Snack | C25: Black coffee + 1 whey scoop | D25: 100 | E25: 130 | F25: =AVERAGE(D25:E25) | G25: 20 | H25: 25 | I25: =AVERAGE(G25:H25) | J25: 1 | K25: 3 | L25: =AVERAGE(J25:K25) | M25: logged
A26: 46272 | B26: Snack | C26: Sweet melon (2 wedges) | D26: 70 | E26: 110 | F26: =AVERAGE(D26:E26) | G26: 1 | H26: 2 | I26: =AVERAGE(G26:H26) | J26: 0 | K26: 1 | L26: =AVERAGE(J26:K26) | M26: logged | N26: Whole fruit - fibre intact; second wedge added
A27: 46272 | B27: Snack | C27: 2 boiled eggs (5pm) | D27: 140 | E27: 156 | F27: =AVERAGE(D27:E27) | G27: 12 | H27: 13 | I27: =AVERAGE(G27:H27) | J27: 10 | K27: 11 | L27: =AVERAGE(J27:K27) | M27: logged | N27: Second egg serving of the day - four eggs total
A28: 46272 | B28: Snack | C28: Red grapes (~100 g) | D28: 60 | E28: 75 | F28: =AVERAGE(D28:E28) | G28: 0.5 | H28: 0.7 | I28: =AVERAGE(G28:H28) | J28: 0 | K28: 0.5 | L28: =AVERAGE(J28:K28) | M28: logged | N28: Portioned into a box rather than eaten from the bunch; some left over
A29: 46272 | B29: Snack | C29: Chatti pathiri chicken (1 slice) | D29: 230 | E29: 320 | F29: =AVERAGE(D29:E29) | G29: 10 | H29: 14 | I29: =AVERAGE(G29:H29) | J29: 12 | K29: 18 | L29: =AVERAGE(J29:K29) | M29: logged | N29: Before dinner. Slice count assumed 1 - double if it was 2
A30: 46273 | B30: Breakfast | C30: Puttu + kadala curry | D30: 420 | E30: 600 | F30: =AVERAGE(D30:E30) | G30: 12 | H30: 16 | I30: =AVERAGE(G30:H30) | J30: 12 | K30: 19 | L30: =AVERAGE(J30:K30) | M30: logged | N30: Mess served puttu rather than the Tuesday masala dosa on the menu
A31: 46273 | B31: Dinner | C31: 2 chapati + green peas curry + 2 boiled eggs | D31: 520 | E31: 676 | F31: =AVERAGE(D31:E31) | G31: 26 | H31: 33 | I31: =AVERAGE(G31:H31) | J31: 22 | K31: 33 | L31: =AVERAGE(J31:K31) | M31: logged | N31: Eggs added to the mess dinner as the protein anchor
A32: 46273 | B32: Lunch | C32: 2 eggs fried without oil + half container ghee rice + small container chicken curry + curd salad | D32: 565 | E32: 786 | F32: =AVERAGE(D32:E32) | G32: 35 | H32: 45 | I32: =AVERAGE(G32:H32) | J32: 29 | K32: 44 | L32: =AVERAGE(J32:K32) | M32: logged | N32: Eggs dry-fried with pepper and salt; rice halved by the user
A33: 46273 | B33: Snack | C33: Black coffee + 1 whey scoop | D33: 100 | E33: 130 | F33: =AVERAGE(D33:E33) | G33: 20 | H33: 25 | I33: =AVERAGE(G33:H33) | J33: 1 | K33: 3 | L33: =AVERAGE(J33:K33) | M33: logged | N33: Scoop 1 of the 3 planned for today
A34: 46273 | B34: Snack | C34: Coca-Cola Zero Sugar (245 ml) | D34: 0 | E34: 2 | F34: =AVERAGE(D34:E34) | G34: 0 | H34: 0 | I34: =AVERAGE(G34:H34) | J34: 0 | K34: 0 | L34: =AVERAGE(J34:K34) | M34: logged | N34: Genuinely zero calorie
A35: 46273 | B35: Snack | C35: 1 whey scoop + water | D35: 100 | E35: 120 | F35: =AVERAGE(D35:E35) | G35: 20 | H35: 25 | I35: =AVERAGE(G35:H35) | J35: 1 | K35: 2 | L35: =AVERAGE(J35:K35) | M35: logged | N35: Closing scoop for the day
A36: 46274 | B36: Breakfast | C36: 1 dosa + egg roast (1 whole egg) | D36: 360 | E36: 490 | F36: =AVERAGE(D36:E36) | G36: 10 | H36: 14 | I36: =AVERAGE(G36:H36) | J36: 17 | K36: 28 | L36: =AVERAGE(J36:K36) | M36: logged | N36: Took a dosa instead of the menu's poratta - the Wednesday cut
A37: 46274 | B37: Dinner | C37: 2 chapati + chicken curry | D37: 480 | E37: 680 | F37: =AVERAGE(D37:E37) | G37: 26 | H37: 36 | I37: =AVERAGE(G37:H37) | J37: 20 | K37: 34 | L37: =AVERAGE(J37:K37) | M37: logged | N37: Mess Wednesday dinner
... A129: 46295 | B129: Lunch | C129: Lebanese mixed grill - 1 saj bread + grilled chicken, kofta and vegetables; no fries, no toum | D129: 520 | E129: 720 | F129: =AVERAGE(D129:E129) | G129: 40 | H129: 55 | I129: =AVERAGE(G129:H129) | J129: 20 | K129: 36 | L129: =AVERAGE(J129:K129) | M129: logged | N129: Fries and garlic sauce both left; 7.7 g protein per 100 kcal

Sheet Daily
A1: Daily totals - logged meals only (pending rows excluded)
A2: Every cell on this sheet is a formula over the Meals sheet. Do not type over them - correct the underlying meal row instead. Mid = midpoint of the low-high range, which is the number to use for trends.
A4: Date | B4: Cal low | C4: Cal high | D4: Cal mid | E4: Protein low (g) | F4: Protein high (g) | G4: Protein mid (g) | H4: Fat low (g) | I4: Fat high (g) | J4: Fat mid (g) | K4: Meals logged | L4: Pending items | M4: vs target (mid)
A5: 46269 | B5: =SUMIFS(Meals!$D$5:$D$129,Meals!$A$5:$A$129,$A5,Meals!$M$5:$M$129,"logged") | C5: =SUMIFS(Meals!$E$5:$E$129,Meals!$A$5:$A$129,$A5,Meals!$M$5:$M$129,"logged") | D5: =AVERAGE(B5:C5) | E5: =SUMIFS(Meals!$G$5:$G$129,Meals!$A$5:$A$129,$A5,Meals!$M$5:$M$129,"logged") | F5: =SUMIFS(Meals!$H$5:$H$129,Meals!$A$5:$A$129,$A5,Meals!$M$5:$M$129,"logged") | G5: =AVERAGE(E5:F5) | H5: =SUMIFS(Meals!$J$5:$J$129,Meals!$A$5:$A$129,$A5,Meals!$M$5:$M$129,"logged") | I5: =SUMIFS(Meals!$K$5:$K$129,Meals!$A$5:$A$129,$A5,Meals!$M$5:$M$129,"logged") | J5: =AVERAGE(H5:I5) | K5: =COUNTIFS(Meals!$A$5:$A$129,$A5,Meals!$M$5:$M$129,"logged") | L5: =COUNTIFS(Meals!$A$5:$A$129,$A5,Meals!$M$5:$M$129,"pending") | M5: =D5-Targets!$B$16
A6: 46270 | B6: =SUMIFS(Meals!$D$5:$D$129,Meals!$A$5:$A$129,$A6,Meals!$M$5:$M$129,"logged") | C6: =SUMIFS(Meals!$E$5:$E$129,Meals!$A$5:$A$129,$A6,Meals!$M$5:$M$129,"logged") | D6: =AVERAGE(B6:C6) | E6: =SUMIFS(Meals!$G$5:$G$129,Meals!$A$5:$A$129,$A6,Meals!$M$5:$M$129,"logged") | F6: =SUMIFS(Meals!$H$5:$H$129,Meals!$A$5:$A$129,$A6,Meals!$M$5:$M$129,"logged") | G6: =AVERAGE(E6:F6) | H6: =SUMIFS(Meals!$J$5:$J$129,Meals!$A$5:$A$129,$A6,Meals!$M$5:$M$129,"logged") | I6: =SUMIFS(Meals!$K$5:$K$129,Meals!$A$5:$A$129,$A6,Meals!$M$5:$M$129,"logged") | J6: =AVERAGE(H6:I6) | K6: =COUNTIFS(Meals!$A$5:$A$129,$A6,Meals!$M$5:$M$129,"logged") | L6: =COUNTIFS(Meals!$A$5:$A$129,$A6,Meals!$M$5:$M$129,"pending") | M6: =D6-Targets!$B$16
A7: 46271 | B7: =SUMIFS(Meals!$D$5:$D$129,Meals!$A$5:$A$129,$A7,Meals!$M$5:$M$129,"logged") | C7: =SUMIFS(Meals!$E$5:$E$129,Meals!$A$5:$A$129,$A7,Meals!$M$5:$M$129,"logged") | D7: =AVERAGE(B7:C7) | E7: =SUMIFS(Meals!$G$5:$G$129,Meals!$A$5:$A$129,$A7,Meals!$M$5:$M$129,"logged") | F7: =SUMIFS(Meals!$H$5:$H$129,Meals!$A$5:$A$129,$A7,Meals!$M$5:$M$129,"logged") | G7: =AVERAGE(E7:F7) | H7: =SUMIFS(Meals!$J$5:$J$129,Meals!$A$5:$A$129,$A7,Meals!$M$5:$M$129,"logged") | I7: =SUMIFS(Meals!$K$5:$K$129,Meals!$A$5:$A$129,$A7,Meals!$M$5:$M$129,"logged") | J7: =AVERAGE(H7:I7) | K7: =COUNTIFS(Meals!$A$5:$A$129,$A7,Meals!$M$5:$M$129,"logged") | L7: =COUNTIFS(Meals!$A$5:$A$129,$A7,Meals!$M$5:$M$129,"pending") | M7: =D7-Targets!$B$16
A8: 46272 | B8: =SUMIFS(Meals!$D$5:$D$129,Meals!$A$5:$A$129,$A8,Meals!$M$5:$M$129,"logged") | C8: =SUMIFS(Meals!$E$5:$E$129,Meals!$A$5:$A$129,$A8,Meals!$M$5:$M$129,"logged") | D8: =AVERAGE(B8:C8) | E8: =SUMIFS(Meals!$G$5:$G$129,Meals!$A$5:$A$129,$A8,Meals!$M$5:$M$129,"logged") | F8: =SUMIFS(Meals!$H$5:$H$129,Meals!$A$5:$A$129,$A8,Meals!$M$5:$M$129,"logged") | G8: =AVERAGE(E8:F8) | H8: =SUMIFS(Meals!$J$5:$J$129,Meals!$A$5:$A$129,$A8,Meals!$M$5:$M$129,"logged") | I8: =SUMIFS(Meals!$K$5:$K$129,Meals!$A$5:$A$129,$A8,Meals!$M$5:$M$129,"logged") | J8: =AVERAGE(H8:I8) | K8: =COUNTIFS(Meals!$A$5:$A$129,$A8,Meals!$M$5:$M$129,"logged") | L8: =COUNTIFS(Meals!$A$5:$A$129,$A8,Meals!$M$5:$M$129,"pending") | M8: =D8-Targets!$B$16
A9: 46273 | B9: =SUMIFS(Meals!$D$5:$D$129,Meals!$A$5:$A$129,$A9,Meals!$M$5:$M$129,"logged") | C9: =SUMIFS(Meals!$E$5:$E$129,Meals!$A$5:$A$129,$A9,Meals!$M$5:$M$129,"logged") | D9: =AVERAGE(B9:C9) | E9: =SUMIFS(Meals!$G$5:$G$129,Meals!$A$5:$A$129,$A9,Meals!$M$5:$M$129,"logged") | F9: =SUMIFS(Meals!$H$5:$H$129,Meals!$A$5:$A$129,$A9,Meals!$M$5:$M$129,"logged") | G9: =AVERAGE(E9:F9) | H9: =SUMIFS(Meals!$J$5:$J$129,Meals!$A$5:$A$129,$A9,Meals!$M$5:$M$129,"logged") | I9: =SUMIFS(Meals!$K$5:$K$129,Meals!$A$5:$A$129,$A9,Meals!$M$5:$M$129,"logged") | J9: =AVERAGE(H9:I9) | K9: =COUNTIFS(Meals!$A$5:$A$129,$A9,Meals!$M$5:$M$129,"logged") | L9: =COUNTIFS(Meals!$A$5:$A$129,$A9,Meals!$M$5:$M$129,"pending") | M9: =D9-Targets!$B$16
A10: 46274 | B10: =SUMIFS(Meals!$D$5:$D$129,Meals!$A$5:$A$129,$A10,Meals!$M$5:$M$129,"logged") | C10: =SUMIFS(Meals!$E$5:$E$129,Meals!$A$5:$A$129,$A10,Meals!$M$5:$M$129,"logged") | D10: =AVERAGE(B10:C10) | E10: =SUMIFS(Meals!$G$5:$G$129,Meals!$A$5:$A$129,$A10,Meals!$M$5:$M$129,"logged") | F10: =SUMIFS(Meals!$H$5:$H$129,Meals!$A$5:$A$129,$A10,Meals!$M$5:$M$129,"logged") | G10: =AVERAGE(E10:F10) | H10: =SUMIFS(Meals!$J$5:$J$129,Meals!$A$5:$A$129,$A10,Meals!$M$5:$M$129,"logged") | I10: =SUMIFS(Meals!$K$5:$K$129,Meals!$A$5:$A$129,$A10,Meals!$M$5:$M$129,"logged") | J10: =AVERAGE(H10:I10) | K10: =COUNTIFS(Meals!$A$5:$A$129,$A10,Meals!$M$5:$M$129,"logged") | L10: =COUNTIFS(Meals!$A$5:$A$129,$A10,Meals!$M$5:$M$129,"pending") | M10: =D10-Targets!$B$16
A11: 46275 | B11: =SUMIFS(Meals!$D$5:$D$129,Meals!$A$5:$A$129,$A11,Meals!$M$5:$M$129,"logged") | C11: =SUMIFS(Meals!$E$5:$E$129,Meals!$A$5:$A$129,$A11,Meals!$M$5:$M$129,"logged") | D11: =AVERAGE(B11:C11) | E11: =SUMIFS(Meals!$G$5:$G$129,Meals!$A$5:$A$129,$A11,Meals!$M$5:$M$129,"logged") | F11: =SUMIFS(Meals!$H$5:$H$129,Meals!$A$5:$A$129,$A11,Meals!$M$5:$M$129,"logged") | G11: =AVERAGE(E11:F11) | H11: =SUMIFS(Meals!$J$5:$J$129,Meals!$A$5:$A$129,$A11,Meals!$M$5:$M$129,"logged") | I11: =SUMIFS(Meals!$K$5:$K$129,Meals!$A$5:$A$129,$A11,Meals!$M$5:$M$129,"logged") | J11: =AVERAGE(H11:I11) | K11: =COUNTIFS(Meals!$A$5:$A$129,$A11,Meals!$M$5:$M$129,"logged") | L11: =COUNTIFS(Meals!$A$5:$A$129,$A11,Meals!$M$5:$M$129,"pending") | M11: =D11-Targets!$B$16
A12: 46276 | B12: =SUMIFS(Meals!$D$5:$D$129,Meals!$A$5:$A$129,$A12,Meals!$M$5:$M$129,"logged") | C12: =SUMIFS(Meals!$E$5:$E$129,Meals!$A$5:$A$129,$A12,Meals!$M$5:$M$129,"logged") | D12: =AVERAGE(B12:C12) | E12: =SUMIFS(Meals!$G$5:$G$129,Meals!$A$5:$A$129,$A12,Meals!$M$5:$M$129,"logged") | F12: =SUMIFS(Meals!$H$5:$H$129,Meals!$A$5:$A$129,$A12,Meals!$M$5:$M$129,"logged") | G12: =AVERAGE(E12:F12) | H12: =SUMIFS(Meals!$J$5:$J$129,Meals!$A$5:$A$129,$A12,Meals!$M$5:$M$129,"logged") | I12: =SUMIFS(Meals!$K$5:$K$129,Meals!$A$5:$A$129,$A12,Meals!$M$5:$M$129,"logged") | J12: =AVERAGE(H12:I12) | K12: =COUNTIFS(Meals!$A$5:$A$129,$A12,Meals!$M$5:$M$129,"logged") | L12: =COUNTIFS(Meals!$A$5:$A$129,$A12,Meals!$M$5:$M$129,"pending") | M12: =D12-Targets!$B$16
A13: 46277 | B13: =SUMIFS(Meals!$D$5:$D$129,Meals!$A$5:$A$129,$A13,Meals!$M$5:$M$129,"logged") | C13: =SUMIFS(Meals!$E$5:$E$129,Meals!$A$5:$A$129,$A13,Meals!$M$5:$M$129,"logged") | D13: =AVERAGE(B13:C13) | E13: =SUMIFS(Meals!$G$5:$G$129,Meals!$A$5:$A$129,$A13,Meals!$M$5:$M$129,"logged") | F13: =SUMIFS(Meals!$H$5:$H$129,Meals!$A$5:$A$129,$A13,Meals!$M$5:$M$129,"logged") | G13: =AVERAGE(E13:F13) | H13: =SUMIFS(Meals!$J$5:$J$129,Meals!$A$5:$A$129,$A13,Meals!$M$5:$M$129,"logged") | I13: =SUMIFS(Meals!$K$5:$K$129,Meals!$A$5:$A$129,$A13,Meals!$M$5:$M$129,"logged") | J13: =AVERAGE(H13:I13) | K13: =COUNTIFS(Meals!$A$5:$A$129,$A13,Meals!$M$5:$M$129,"logged") | L13: =COUNTIFS(Meals!$A$5:$A$129,$A13,Meals!$M$5:$M$129,"pending") | M13: =D13-Targets!$B$16
A14: 46278 | B14: =SUMIFS(Meals!$D$5:$D$129,Meals!$A$5:$A$129,$A14,Meals!$M$5:$M$129,"logged") | C14: =SUMIFS(Meals!$E$5:$E$129,Meals!$A$5:$A$129,$A14,Meals!$M$5:$M$129,"logged") | D14: =AVERAGE(B14:C14) | E14: =SUMIFS(Meals!$G$5:$G$129,Meals!$A$5:$A$129,$A14,Meals!$M$5:$M$129,"logged") | F14: =SUMIFS(Meals!$H$5:$H$129,Meals!$A$5:$A$129,$A14,Meals!$M$5:$M$129,"logged") | G14: =AVERAGE(E14:F14) | H14: =SUMIFS(Meals!$J$5:$J$129,Meals!$A$5:$A$129,$A14,Meals!$M$5:$M$129,"logged") | I14: =SUMIFS(Meals!$K$5:$K$129,Meals!$A$5:$A$129,$A14,Meals!$M$5:$M$129,"logged") | J14: =AVERAGE(H14:I14) | K14: =COUNTIFS(Meals!$A$5:$A$129,$A14,Meals!$M$5:$M$129,"logged") | L14: =COUNTIFS(Meals!$A$5:$A$129,$A14,Meals!$M$5:$M$129,"pending") | M14: =D14-Targets!$B$16
A15: 46279 | B15: =SUMIFS(Meals!$D$5:$D$129,Meals!$A$5:$A$129,$A15,Meals!$M$5:$M$129,"logged") | C15: =SUMIFS(Meals!$E$5:$E$129,Meals!$A$5:$A$129,$A15,Meals!$M$5:$M$129,"logged") | D15: =AVERAGE(B15:C15) | E15: =SUMIFS(Meals!$G$5:$G$129,Meals!$A$5:$A$129,$A15,Meals!$M$5:$M$129,"logged") | F15: =SUMIFS(Meals!$H$5:$H$129,Meals!$A$5:$A$129,$A15,Meals!$M$5:$M$129,"logged") | G15: =AVERAGE(E15:F15) | H15: =SUMIFS(Meals!$J$5:$J$129,Meals!$A$5:$A$129,$A15,Meals!$M$5:$M$129,"logged") | I15: =SUMIFS(Meals!$K$5:$K$129,Meals!$A$5:$A$129,$A15,Meals!$M$5:$M$129,"logged") | J15: =AVERAGE(H15:I15) | K15: =COUNTIFS(Meals!$A$5:$A$129,$A15,Meals!$M$5:$M$129,"logged") | L15: =COUNTIFS(Meals!$A$5:$A$129,$A15,Meals!$M$5:$M$129,"pending") | M15: =D15-Targets!$B$16
A16: 46280 | B16: =SUMIFS(Meals!$D$5:$D$129,Meals!$A$5:$A$129,$A16,Meals!$M$5:$M$129,"logged") | C16: =SUMIFS(Meals!$E$5:$E$129,Meals!$A$5:$A$129,$A16,Meals!$M$5:$M$129,"logged") | D16: =AVERAGE(B16:C16) | E16: =SUMIFS(Meals!$G$5:$G$129,Meals!$A$5:$A$129,$A16,Meals!$M$5:$M$129,"logged") | F16: =SUMIFS(Meals!$H$5:$H$129,Meals!$A$5:$A$129,$A16,Meals!$M$5:$M$129,"logged") | G16: =AVERAGE(E16:F16) | H16: =SUMIFS(Meals!$J$5:$J$129,Meals!$A$5:$A$129,$A16,Meals!$M$5:$M$129,"logged") | I16: =SUMIFS(Meals!$K$5:$K$129,Meals!$A$5:$A$129,$A16,Meals!$M$5:$M$129,"logged") | J16: =AVERAGE(H16:I16) | K16: =COUNTIFS(Meals!$A$5:$A$129,$A16,Meals!$M$5:$M$129,"logged") | L16: =COUNTIFS(Meals!$A$5:$A$129,$A16,Meals!$M$5:$M$129,"pending") | M16: =D16-Targets!$B$16
... A31: 46295 | B31: =SUMIFS(Meals!$D$5:$D$129,Meals!$A$5:$A$129,$A31,Meals!$M$5:$M$129,"logged") | C31: =SUMIFS(Meals!$E$5:$E$129,Meals!$A$5:$A$129,$A31,Meals!$M$5:$M$129,"logged") | D31: =AVERAGE(B31:C31) | E31: =SUMIFS(Meals!$G$5:$G$129,Meals!$A$5:$A$129,$A31,Meals!$M$5:$M$129,"logged") | F31: =SUMIFS(Meals!$H$5:$H$129,Meals!$A$5:$A$129,$A31,Meals!$M$5:$M$129,"logged") | G31: =AVERAGE(E31:F31) | H31: =SUMIFS(Meals!$J$5:$J$129,Meals!$A$5:$A$129,$A31,Meals!$M$5:$M$129,"logged") | I31: =SUMIFS(Meals!$K$5:$K$129,Meals!$A$5:$A$129,$A31,Meals!$M$5:$M$129,"logged") | J31: =AVERAGE(H31:I31) | K31: =COUNTIFS(Meals!$A$5:$A$129,$A31,Meals!$M$5:$M$129,"logged") | L31: =COUNTIFS(Meals!$A$5:$A$129,$A31,Meals!$M$5:$M$129,"pending") | M31: =D31-Targets!$B$16

Sheet Weights
A1: Weigh-ins
A2: Weigh same time, same conditions - first thing, after the toilet, before food or drink. Add a row per weigh-in; the Targets sheet reads the latest entry automatically. Read the trailing average, not the raw number.
A4: Date | B4: Weight (kg) | C4: Change | D4: Since start | E4: Trailing avg (7) | F4: Note
A5: 46270 | B5: 91.5 | D5: =B5-$B$5 | E5: =AVERAGE(B5:B5) | F5: Starting weight - stated by user
A6: 46272 | B6: 90.75 | C6: =B6-B5 | D6: =B6-$B$5 | E6: =AVERAGE(B5:B6) | F6: Morning weigh-in
A7: 46274 | B7: 90.3 | C7: =B7-B6 | D7: =B7-$B$5 | E7: =AVERAGE(B5:B7) | F7: Morning weigh-in
A8: 46276 | B8: 90.05 | C8: =B8-B7 | D8: =B8-$B$5 | E8: =AVERAGE(B5:B8) | F8: Morning weigh-in
A9: 46281 | B9: 90.15 | C9: =B9-B8 | D9: =B9-$B$5 | E9: =AVERAGE(B5:B9) | F9: Morning weigh-in - user noted different clothing from previous weigh-ins
A10: 46282 | B10: 90.05 | C10: =B10-B9 | D10: =B10-$B$5 | E10: =AVERAGE(B5:B10) | F10: Morning weigh-in
A11: 46283 | B11: 89.55 | C11: =B11-B10 | D11: =B11-$B$5 | E11: =AVERAGE(B5:B11) | F11: Morning weigh-in - first reading under 90 kg
A12: 46284 | B12: 89.45 | C12: =B12-B11 | D12: =B12-$B$5 | E12: =AVERAGE(B6:B12) | F12: Morning weigh-in
A13: 46287 | B13: 89.5 | C13: =B13-B12 | D13: =B13-$B$5 | E13: =AVERAGE(B7:B13) | F13: Morning weigh-in
A14: 46288 | B14: 89.6 | C14: =B14-B13 | D14: =B14-$B$5 | E14: =AVERAGE(B8:B14) | F14: Morning weigh-in
A15: 46289 | B15: 89.15 | C15: =B15-B14 | D15: =B15-$B$5 | E15: =AVERAGE(B9:B15) | F15: Morning weigh-in - largest single-day drop in the log
A16: 46290 | B16: 88.75 | C16: =B16-B15 | D16: =B16-$B$5 | E16: =AVERAGE(B10:B16) | F16: Morning weigh-in - second consecutive drop; second sub-89.3 reading
A18: A drop in the first week is mostly water and glycogen, not fat. Judge the trend over 2-3 weeks, and change the activity multiplier on Targets only then.

Sheet Measurements
A1: Measurements
A2: Measure cold, same time of day, same spot, relaxed - arm at mid-bicep, waist at the navel. Fortnightly is enough. What matters is not any single number but waist falling while arm circumference holds: that is fat leaving and muscle staying, which the scale alone cannot show.
A4: Date | B4: Waist (cm) | C4: Arm relaxed | D4: Arm flexed | E4: Chest | F4: Hips | G4: Thigh | H4: Calf | I4: Waist change | J4: Arm change | K4: Note
A5: No measurements yet - add a row to measurements.csv.

Sheet Mess Plan
A1: Grill Spot mess - weekly plan
A2: The menu is fixed, so the levers are portion control and added protein. Set how many bread items to skip and whether to halve the rice, per day, in the yellow columns; the sheet works out the calories that frees and how many whey scoops fit inside the target.
A4: Assumptions
A5: Bread item - kcal | B5: 115 | C5: Dinner bread is chapati, not porotta - roughly half the calories and a third of the fat.
A6: Bread item - protein (g) | B6: 3.5
A7: Halving rice - kcal saved | B7: 200 | C7: Applies to a full 'Meals' or ghee-rice plate.
A8: Halving rice - protein (g) | B8: 2
A9: Whey scoop - kcal | B9: 115 | C9: 19.6 g protein per 100 kcal, vs 3.1 for the mess.
A10: Whey scoop - protein (g) | B10: 22.5
A13: Day | B13: Morning | C13: Lunch | D13: Dinner | E13: Kcal as served | F13: Protein as served | G13: Bread items to skip | H13: Halve rice? (1/0) | I13: Kcal after cuts | J13: Protein after cuts | K13: Room to target | L13: Scoops that fit | M13: Protein with scoops
A14: Monday | B14: Poori, baji | C14: Meals (barik/mota rice) | D14: Chicken curry + 2 chapati | E14: 1885 | F14: 72.5 | G14: 0 | H14: 1 | I14: =E14-G14*$B$5-H14*$B$7 | J14: =F14-G14*$B$6-H14*$B$8 | K14: =Targets!$B$16-I14 | L14: =MAX(0,ROUNDDOWN(K14/$B$9,0)) | M14: =J14+L14*$B$10
A15: Tuesday | B15: Masala dosa | C15: Ghee rice + chicken curry | D15: Green peas + 2 chapati | E15: 1565 | F15: 54.5 | G15: 0 | H15: 1 | I15: =E15-G15*$B$5-H15*$B$7 | J15: =F15-G15*$B$6-H15*$B$8 | K15: =Targets!$B$16-I15 | L15: =MAX(0,ROUNDDOWN(K15/$B$9,0)) | M15: =J15+L15*$B$10
A16: Wednesday | B16: Poratta + egg roast | C16: Meals (barik/mota rice) | D16: Chicken traditional curry + 2 chapati | E16: 2160 | F16: 88.5 | G16: 0 | H16: 1 | I16: =E16-G16*$B$5-H16*$B$7 | J16: =F16-G16*$B$6-H16*$B$8 | K16: =Targets!$B$16-I16 | L16: =MAX(0,ROUNDDOWN(K16/$B$9,0)) | M16: =J16+L16*$B$10
A17: Thursday | B17: Ghee roast | C17: Meals (barik/mota rice) | D17: Gobbi chilly + 2 chapati | E17: 1830 | F17: 54 | G17: 0 | H17: 1 | I17: =E17-G17*$B$5-H17*$B$7 | J17: =F17-G17*$B$6-H17*$B$8 | K17: =Targets!$B$16-I17 | L17: =MAX(0,ROUNDDOWN(K17/$B$9,0)) | M17: =J17+L17*$B$10
A18: Friday | B18: Idly set | C18: Chicken biriyani | D18: Kadala curry + 2 chapati | E18: 1455 | F18: 59 | G18: 0 | H18: 0 | I18: =E18-G18*$B$5-H18*$B$7 | J18: =F18-G18*$B$6-H18*$B$8 | K18: =Targets!$B$16-I18 | L18: =MAX(0,ROUNDDOWN(K18/$B$9,0)) | M18: =J18+L18*$B$10
A19: Saturday | B19: Dosa set | C19: Meals (barik/mota rice) | D19: Chicken varutharachathu + 2 chapati | E19: 2100 | F19: 77 | G19: 0 | H19: 1 | I19: =E19-G19*$B$5-H19*$B$7 | J19: =F19-G19*$B$6-H19*$B$8 | K19: =Targets!$B$16-I19 | L19: =MAX(0,ROUNDDOWN(K19/$B$9,0)) | M19: =J19+L19*$B$10
A20: Sunday | B20: Kadala curry + poratta | C20: Ghee rice + chicken curry | D20: Egg roast + 2 chapati | E20: 1875 | F20: 69 | G20: 0 | H20: 1 | I20: =E20-G20*$B$5-H20*$B$7 | J20: =F20-G20*$B$6-H20*$B$8 | K20: =Targets!$B$16-I20 | L20: =MAX(0,ROUNDDOWN(K20/$B$9,0)) | M20: =J20+L20*$B$10
A22: As served the mess averages ~1,904 kcal and ~60 g of protein - 3.1 g per 100 kcal. It fills 95% of the calorie target while delivering under half the protein floor.
A23: That is why portion control is not optional here: without cutting, there is only ~100 kcal of room left for protein, which is less than one scoop.
A24: Bread items are the cheapest cut - ~205 kcal for ~5 g of protein each.

Sheet Trends
A1: Trends - averages of the daily midpoints
A2: Targets come from the Targets sheet - change them there, not here.
A4: Overall
A5: Days logged | B5: =COUNT(Daily!$A$5:$A$31)
A6: Avg calories/day (mid) | B6: =IFERROR(AVERAGE(Daily!$D$5:$D$31),0)
A7: Avg protein/day (mid, g) | B7: =IFERROR(AVERAGE(Daily!$G$5:$G$31),0)
A8: Avg fat/day (mid, g) | B8: =IFERROR(AVERAGE(Daily!$J$5:$J$31),0)
A9: Avg vs calorie target | B9: =IFERROR(B6-Targets!$B$16,0)
A10: Avg deficit vs maintenance | B10: =IFERROR(Targets!$B$15-B6,0)
A11: Implied loss (kg/week) | B11: =IFERROR((Targets!$B$15-B6)*7/Targets!$B$11,0)
A12: Days hitting protein target | B12: =COUNTIFS(Daily!$G$5:$G$31,">="&Targets!$B$20)
A13: Total pending (unconfirmed) items | B13: =SUM(Daily!$L$5:$L$31)
A15: Weekly (week starting Monday)
A16: Week start | B16: Week end | C16: Days logged | D16: Avg cal/day (mid) | E16: Avg protein/day (mid, g) | F16: Avg fat/day (mid, g)
A17: 46265 | B17: 46271 | C17: =COUNTIFS(Daily!$A$5:$A$31,">="&$A17,Daily!$A$5:$A$31,"<="&$B17) | D17: =IFERROR(AVERAGEIFS(Daily!$D$5:$D$31,Daily!$A$5:$A$31,">="&$A17,Daily!$A$5:$A$31,"<="&$B17),0) | E17: =IFERROR(AVERAGEIFS(Daily!$G$5:$G$31,Daily!$A$5:$A$31,">="&$A17,Daily!$A$5:$A$31,"<="&$B17),0) | F17: =IFERROR(AVERAGEIFS(Daily!$J$5:$J$31,Daily!$A$5:$A$31,">="&$A17,Daily!$A$5:$A$31,"<="&$B17),0)
A18: 46272 | B18: 46278 | C18: =COUNTIFS(Daily!$A$5:$A$31,">="&$A18,Daily!$A$5:$A$31,"<="&$B18) | D18: =IFERROR(AVERAGEIFS(Daily!$D$5:$D$31,Daily!$A$5:$A$31,">="&$A18,Daily!$A$5:$A$31,"<="&$B18),0) | E18: =IFERROR(AVERAGEIFS(Daily!$G$5:$G$31,Daily!$A$5:$A$31,">="&$A18,Daily!$A$5:$A$31,"<="&$B18),0) | F18: =IFERROR(AVERAGEIFS(Daily!$J$5:$J$31,Daily!$A$5:$A$31,">="&$A18,Daily!$A$5:$A$31,"<="&$B18),0)
A19: 46279 | B19: 46285 | C19: =COUNTIFS(Daily!$A$5:$A$31,">="&$A19,Daily!$A$5:$A$31,"<="&$B19) | D19: =IFERROR(AVERAGEIFS(Daily!$D$5:$D$31,Daily!$A$5:$A$31,">="&$A19,Daily!$A$5:$A$31,"<="&$B19),0) | E19: =IFERROR(AVERAGEIFS(Daily!$G$5:$G$31,Daily!$A$5:$A$31,">="&$A19,Daily!$A$5:$A$31,"<="&$B19),0) | F19: =IFERROR(AVERAGEIFS(Daily!$J$5:$J$31,Daily!$A$5:$A$31,">="&$A19,Daily!$A$5:$A$31,"<="&$B19),0)
A20: 46286 | B20: 46292 | C20: =COUNTIFS(Daily!$A$5:$A$31,">="&$A20,Daily!$A$5:$A$31,"<="&$B20) | D20: =IFERROR(AVERAGEIFS(Daily!$D$5:$D$31,Daily!$A$5:$A$31,">="&$A20,Daily!$A$5:$A$31,"<="&$B20),0) | E20: =IFERROR(AVERAGEIFS(Daily!$G$5:$G$31,Daily!$A$5:$A$31,">="&$A20,Daily!$A$5:$A$31,"<="&$B20),0) | F20: =IFERROR(AVERAGEIFS(Daily!$J$5:$J$31,Daily!$A$5:$A$31,">="&$A20,Daily!$A$5:$A$31,"<="&$B20),0)
A21: 46293 | B21: 46299 | C21: =COUNTIFS(Daily!$A$5:$A$31,">="&$A21,Daily!$A$5:$A$31,"<="&$B21) | D21: =IFERROR(AVERAGEIFS(Daily!$D$5:$D$31,Daily!$A$5:$A$31,">="&$A21,Daily!$A$5:$A$31,"<="&$B21),0) | E21: =IFERROR(AVERAGEIFS(Daily!$G$5:$G$31,Daily!$A$5:$A$31,">="&$A21,Daily!$A$5:$A$31,"<="&$B21),0) | F21: =IFERROR(AVERAGEIFS(Daily!$J$5:$J$31,Daily!$A$5:$A$31,">="&$A21,Daily!$A$5:$A$31,"<="&$B21),0)
A23: Monthly
A24: Month start | B24: Month end | C24: Days logged | D24: Avg cal/day (mid) | E24: Avg protein/day (mid, g) | F24: Avg fat/day (mid, g)
A25: 46266 | B25: 46295 | C25: =COUNTIFS(Daily!$A$5:$A$31,">="&$A25,Daily!$A$5:$A$31,"<="&$B25) | D25: =IFERROR(AVERAGEIFS(Daily!$D$5:$D$31,Daily!$A$5:$A$31,">="&$A25,Daily!$A$5:$A$31,"<="&$B25),0) | E25: =IFERROR(AVERAGEIFS(Daily!$G$5:$G$31,Daily!$A$5:$A$31,">="&$A25,Daily!$A$5:$A$31,"<="&$B25),0) | F25: =IFERROR(AVERAGEIFS(Daily!$J$5:$J$31,Daily!$A$5:$A$31,">="&$A25,Daily!$A$5:$A$31,"<="&$B25),0)
A27: Averages cover only the days present in the log; a part-logged day (today's dinner still to come) drags its average down.

Sheet Targets
A1: Targets
A2: Edit the yellow input cells only. BMR uses Mifflin-St Jeor, the equation recommended for this purpose. Everything below the inputs is a formula, so dropping the weight here re-derives maintenance, the calorie target and the carb allowance automatically.
A4: Inputs
A5: Weight (kg) | B5: =INDEX(Weights!$B$5:$B$500,COUNT(Weights!$B$5:$B$500)) | C5: Latest entry on the Weights sheet - add a weigh-in there and everything below re-derives. Do not type over it.
A6: Height (cm) | B6: 162.5 | C6: Source: stated by user.
A7: Age (years) | B7: 33 | C7: Source: stated by user (turns 33 on 2026-09-15).
A8: Sex constant | B8: 5 | C8: Mifflin-St Jeor term: +5 male, -161 female.
A9: Activity multiplier | B9: 1.52 | C9: 1.52, revised 2026-09-11 from Apple Watch: 8,237 steps/day averaged over a month is ~5.6 km, well above the sedentary baseline the old 1.45 assumed. Still an estimate - the trailing weight average is the arbiter.
A10: Daily deficit (kcal) | B10: 550 | C10: 550/day = 0.5 kg/week. Assumption, not a measurement.
A11: kcal per kg of body fat | B11: 7700 | C11: Standard 7,700 kcal/kg conversion.
A13: Derived
A14: BMR (Mifflin-St Jeor) | B14: =10*B5+6.25*B6-5*B7+B8 | C14: Resting burn: what the body uses doing nothing.
A15: Maintenance (TDEE) | B15: =B14*B9 | C15: Estimate. The scale over 2-3 weeks is the real measurement.
A16: CALORIE TARGET | B16: =B15-B10 | C16: The number to eat.
A17: Projected loss (kg/week) | B17: =B10*7/B11
A18: BMI | B18: =B5/(B6/100)^2 | C18: Worth a GP or dietitian check alongside this plan.
A20: Macros at the calorie target
A21: Protein target low (g) | B21: 130 | C21: ~2.1 g/kg of estimated lean mass - the level that protects muscle in a deficit while training 6 days.
A22: Protein target high (g) | B22: 145
A23: Fat floor (g) | B23: 55 | C23: ~0.6 g/kg. A floor for hormone health, not a goal to hit.
A24: Carb allowance (g) | B24: =(B16-B21*4-B23*9)/4 | C24: Whatever is left once protein and the fat floor are paid for. Fuels the PPL work.
A26: Where maintenance comes from
A27: Sedentary baseline (BMR x 1.2) | B27: =B14*1.2 | C27: Living, digestion, and the ~3,500-5,000 steps a desk-bound day produces.
A28: Walking NEAT above sedentary | B28: 150 | C28: Apple Watch: 8,237 steps/day averaged over a month, ~5.6 km. The part above a sedentary baseline, at 0.5 kcal per kg per km.
A29: Training allowance | B29: =B15-B27-B28 | C29: What is left for the gym once living and walking are paid for.
A30: Sessions per week | B30: 6 | C30: 6-day PPL split.
A31: Implied kcal per session | B31: =B29*7/B30 | C31: Sanity check: resistance training runs ~5-7 kcal/min, so 45-90 min at this bodyweight is ~225-630 kcal. If sessions are short, this allowance is generous and the multiplier should come down - but let the scale decide, not this cell.
A32: Optional extra activity - modelled but NOT in the target above | C32: Deliberately excluded from the calorie target. Activity credited in advance is the commonest way a deficit quietly disappears; let the scale confirm it first, then decide whether to eat it back.
A33: Daily walk (km) | B33: 0 | C33: Now zero: the daily walk is inside the 1.52 multiplier, set from measured step count. Use this block only for walking ON TOP of the usual 8,200 steps.
A34: Net kcal per kg per km | B34: 0.5 | C34: Net of what would have been burned sitting. Gross is ~0.65.
A35: Calisthenics (kcal/day) | B35: 67 | C35: 60 push-ups ~24 kcal, 36 pull-ups ~43. Real training stimulus, small calorie cost.
A36: Extra burn | B36: =B33*B34*B5+B35
A37: Adjusted maintenance | B37: =B15+B36
A38: Implied multiplier | B38: =B37/B14 | C38: Against the 1.45 used above.
A39: Deficit at the current target | B39: =B37-B16
A40: Implied loss (kg/week) | B40: =B39*7/B11

Sheet Reference
A1: Per-item working estimates
A2: Photo-based estimates, kept here so the same item is costed the same way every time. These are assumptions, not measured values - update one and re-cost the meals that use it.
A4: Item | B4: Cal low | C4: Cal high | D4: Cal mid | E4: Protein | F4: Notes
A5: Dosa (plain/crisp) | B5: 180 | C5: 220 | D5: =AVERAGE(B5:C5) | E5: ~3 g each | F5: Per dosa
A6: Dosa (set dosa / appam style) | B6: 120 | C6: 150 | D6: =AVERAGE(B6:C6) | E6: ~3 g each | F6: Softer/thicker style
A7: Appam / palappam (1) | B7: 120 | C7: 150 | D7: =AVERAGE(B7:C7) | E7: ~2.5-3.5 g each | F7: Fermented rice batter with coconut milk
A8: Puttu (1 cylinder ~180-220 g) | B8: 220 | C8: 300 | D8: =AVERAGE(B8:C8) | E8: ~4-6 g | F8: Steamed rice flour and coconut - no frying oil at all
A9: Potato bhaji / curry (small bowl) | B9: 150 | C9: 220 | D9: =AVERAGE(B9:C9) | E9: ~3-4 g | F9: Kerala style; oil and coconut milk carry the calories
A10: Sambar (with veg) | B10: 130 | C10: 160 | D10: =AVERAGE(B10:C10) | E10: ~4-6 g | F10: Per serving
A11: Coconut chutney (~2 tbsp) | B11: 90 | C11: 110 | D11: =AVERAGE(B11:C11) | E11: ~1-2 g | F11: Fat-dense - the usual thing to cut
A12: Red/tomato chutney (~2 tbsp) | B12: 40 | C12: 70 | D12: =AVERAGE(B12:C12) | E12: ~1 g
A13: Chicken biryani (half plate) | B13: 450 | C13: 600 | D13: =AVERAGE(B13:C13) | E13: ~22-30 g | F13: Rice + 2 pieces
A14: Raita (small) | B14: 50 | C14: 80 | D14: =AVERAGE(B14:C14) | E14: ~2-4 g
A15: Maida porotta | B15: 160 | C15: 250 | D15: =AVERAGE(B15:C15) | E15: ~4-6 g each | F15: Refined flour + layered oil/ghee
A16: Chapati (1) | B16: 100 | C16: 130 | D16: =AVERAGE(B16:C16) | E16: ~3-4 g each | F16: Whole wheat with little or no oil - about half a porotta's calories and a third of its fat
A17: Chicken roll - breadcrumbed and deep-fried (1) | B17: 290 | C17: 400 | D17: =AVERAGE(B17:C17) | E17: ~10-15 g | F17: Mostly bread and absorbed frying oil; the chicken filling is a thin layer. 3.6 g protein per 100 kcal
A18: Chatti pathiri chicken (1 slice ~100-120 g) | B18: 230 | C18: 320 | D18: =AVERAGE(B18:C18) | E18: ~10-14 g | F18: Layered maida pathiri with chicken masala and an egg-milk binder; ghee-rich
A19: Uzhunnu vada / medu vada (1) | B19: 130 | C19: 180 | D19: =AVERAGE(B19:C19) | E19: ~3.5-5 g each | F19: Deep-fried urad dal - protein-bearing but fat-dense
A20: Kadala curry (1 container) | B20: 200 | C20: 300 | D20: =AVERAGE(B20:C20) | E20: ~8-10 g
A21: Fish fry (1 piece pan-fried) | B21: 150 | C21: 220 | D21: =AVERAGE(B21:C21) | E21: ~15-20 g
A22: Grilled sea bream (1 whole ~300-400 g) | B22: 250 | C22: 400 | D22: =AVERAGE(B22:C22) | E22: ~35-50 g | F22: Lean white fish; best protein-per-calorie item available. Most fat is the grill oil
A23: Matthi / sardine (2-3 fish taken without gravy) | B23: 150 | C23: 230 | D23: =AVERAGE(B23:C23) | E23: ~18-26 g | F23: Oily fish - denser than white fish but excellent protein. Leaving the gravy saves ~100 kcal and ~10 g fat
A24: Grilled chicken breast (100 g skinless) | B24: 160 | C24: 180 | D24: =AVERAGE(B24:C24) | E24: ~30-32 g | F24: Best protein-per-calorie item in this list
A25: Grilled chicken breast (150 g skinless) | B25: 240 | C25: 270 | D25: =AVERAGE(B25:C25) | E25: ~45-48 g
A26: Honest Bowl - Grilled Chicken and Rice Bowl | B26: 550 | C26: 710 | D26: =AVERAGE(B26:C26) | E26: 42-48 g | F26: Menu states 42 g protein; chicken + jasmine rice + sweet potato. Sauce served separately
A27: Brown/mushroom sauce (side pot) | B27: 50 | C27: 120 | D27: =AVERAGE(B27:C27) | E27: ~1-2 g | F27: Often cream or butter based - the variable in a bowl like this
A28: Honest Bowl - Tofu Delight Bowl | B28: 420 | C28: 560 | D28: =AVERAGE(B28:C28) | E28: ~20 g | F28: Menu states 20 g; jasmine rice + cajun tofu + grilled eggplant. Half the protein of the chicken bowl at the same price
A29: Chicken curry (1 takeaway container) | B29: 280 | C29: 420 | D29: =AVERAGE(B29:C29) | E29: ~20-28 g | F29: Kerala style; oil and coconut carry most of the calories
A30: Grilled chicken quarter (skin on) | B30: 250 | C30: 320 | D30: =AVERAGE(B30:C30) | E30: ~28-33 g | F30: Skin adds ~12-15 g fat over breast
A31: Whole grilled chicken - skin eaten | B31: 1200 | C31: 1600 | D31: =AVERAGE(B31:C31) | E31: ~125-140 g | F31: A 900-1200 g raw bird. Skin carries most of the fat
A32: Whole grilled chicken - skin removed | B32: 750 | C32: 900 | D32: =AVERAGE(B32:C32) | E32: ~120-135 g | F32: Same protein for roughly half the calories
A33: Half grilled chicken - skin removed | B33: 375 | C33: 450 | D33: =AVERAGE(B33:C33) | E33: ~60-68 g | F33: The realistic single portion; 15.6 g protein per 100 kcal
A34: Half grilled chicken - skin on | B34: 600 | C34: 800 | D34: =AVERAGE(B34:C34) | E34: ~62-70 g | F34: As served. The skin adds ~290 kcal and ~29 g fat for ~2 g protein
A35: Quarter grilled chicken - skin removed | B35: 190 | C35: 225 | D35: =AVERAGE(B35:C35) | E35: ~30-34 g | F35: Half the above; the size that fits inside a normal day
A36: Garlic sauce / toum (1 tbsp) | B36: 90 | C36: 110 | D36: =AVERAGE(B36:C36) | E36: 0 g | F36: Essentially emulsified oil - the hidden cost at a grill
A37: Khubz / pita (1 large) | B37: 250 | C37: 300 | D37: =AVERAGE(B37:C37) | E37: ~8-9 g
A38: Barik/basmati rice (half container cooked) | B38: 200 | C38: 280 | D38: =AVERAGE(B38:C38) | E38: ~4-5 g
A39: Fresh pineapple juice (350-450 ml) | B39: 175 | C39: 240 | D39: =AVERAGE(B39:C39) | E39: ~1-2 g | F39: No added sugar but ~35-45 g natural sugar; no fibre; almost no protein
A40: Fresh orange juice (350-450 ml) | B40: 155 | C40: 205 | D40: =AVERAGE(B40:C40) | E40: ~2-3 g | F40: No added sugar but ~32-40 g natural sugar; no fibre
A41: Whey scoop (in water) | B41: 100 | C41: 120 | D41: =AVERAGE(B41:C41) | E41: ~20-25 g
...
